[2022-03-27 04:04:08,814] {taskinstance.py:1032} INFO - Dependencies all met for <TaskInstance: data_ingestion_gcs_dag.format_to_parquet_task manual__2022-03-27T04:03:48.472709+00:00 [queued]>
[2022-03-27 04:04:08,864] {taskinstance.py:1032} INFO - Dependencies all met for <TaskInstance: data_ingestion_gcs_dag.format_to_parquet_task manual__2022-03-27T04:03:48.472709+00:00 [queued]>
[2022-03-27 04:04:08,866] {taskinstance.py:1238} INFO - 
--------------------------------------------------------------------------------
[2022-03-27 04:04:08,869] {taskinstance.py:1239} INFO - Starting attempt 1 of 2
[2022-03-27 04:04:08,874] {taskinstance.py:1240} INFO - 
--------------------------------------------------------------------------------
[2022-03-27 04:04:08,920] {taskinstance.py:1259} INFO - Executing <Task(PythonOperator): format_to_parquet_task> on 2022-03-27 04:03:48.472709+00:00
[2022-03-27 04:04:08,944] {standard_task_runner.py:52} INFO - Started process 1336 to run task
[2022-03-27 04:04:08,969] {standard_task_runner.py:76} INFO - Running: ['***', 'tasks', 'run', 'data_ingestion_gcs_dag', 'format_to_parquet_task', 'manual__2022-03-27T04:03:48.472709+00:00', '--job-id', '30', '--raw', '--subdir', 'DAGS_FOLDER/data_ingestion_gcs_dag.py', '--cfg-path', '/tmp/tmpj2qhpevf', '--error-file', '/tmp/tmpu21f8gcd']
[2022-03-27 04:04:08,978] {standard_task_runner.py:77} INFO - Job 30: Subtask format_to_parquet_task
[2022-03-27 04:04:09,371] {logging_mixin.py:109} INFO - Running <TaskInstance: data_ingestion_gcs_dag.format_to_parquet_task manual__2022-03-27T04:03:48.472709+00:00 [running]> on host f98077e2e921
[2022-03-27 04:04:10,011] {taskinstance.py:1426} INFO - Exporting the following env vars:
AIRFLOW_CTX_DAG_OWNER=***
AIRFLOW_CTX_DAG_ID=data_ingestion_gcs_dag
AIRFLOW_CTX_TASK_ID=format_to_parquet_task
AIRFLOW_CTX_EXECUTION_DATE=2022-03-27T04:03:48.472709+00:00
AIRFLOW_CTX_DAG_RUN_ID=manual__2022-03-27T04:03:48.472709+00:00
[2022-03-27 04:04:11,735] {taskinstance.py:1700} ERROR - Task failed with exception
Traceback (most recent call last):
  File "/home/airflow/.local/lib/python3.7/site-packages/airflow/models/taskinstance.py", line 1329, in _run_raw_task
    self._execute_task_with_callbacks(context)
  File "/home/airflow/.local/lib/python3.7/site-packages/airflow/models/taskinstance.py", line 1455, in _execute_task_with_callbacks
    result = self._execute_task(context, self.task)
  File "/home/airflow/.local/lib/python3.7/site-packages/airflow/models/taskinstance.py", line 1511, in _execute_task
    result = execute_callable(context=context)
  File "/home/airflow/.local/lib/python3.7/site-packages/airflow/operators/python.py", line 174, in execute
    return_value = self.execute_callable()
  File "/home/airflow/.local/lib/python3.7/site-packages/airflow/operators/python.py", line 185, in execute_callable
    return self.python_callable(*self.op_args, **self.op_kwargs)
  File "/opt/airflow/dags/data_ingestion_gcs_dag.py", line 35, in format_to_parquet
    table = pv.read_csv(csv_file)
NameError: name 'csv_file' is not defined
[2022-03-27 04:04:11,842] {taskinstance.py:1277} INFO - Marking task as UP_FOR_RETRY. dag_id=data_ingestion_gcs_dag, task_id=format_to_parquet_task, execution_date=20220327T040348, start_date=20220327T040408, end_date=20220327T040411
[2022-03-27 04:04:12,067] {standard_task_runner.py:92} ERROR - Failed to execute job 30 for task format_to_parquet_task
Traceback (most recent call last):
  File "/home/airflow/.local/lib/python3.7/site-packages/airflow/task/task_runner/standard_task_runner.py", line 85, in _start_by_fork
    args.func(args, dag=self.dag)
  File "/home/airflow/.local/lib/python3.7/site-packages/airflow/cli/cli_parser.py", line 48, in command
    return func(*args, **kwargs)
  File "/home/airflow/.local/lib/python3.7/site-packages/airflow/utils/cli.py", line 92, in wrapper
    return f(*args, **kwargs)
  File "/home/airflow/.local/lib/python3.7/site-packages/airflow/cli/commands/task_command.py", line 298, in task_run
    _run_task_by_selected_method(args, dag, ti)
  File "/home/airflow/.local/lib/python3.7/site-packages/airflow/cli/commands/task_command.py", line 107, in _run_task_by_selected_method
    _run_raw_task(args, ti)
  File "/home/airflow/.local/lib/python3.7/site-packages/airflow/cli/commands/task_command.py", line 184, in _run_raw_task
    error_file=args.error_file,
  File "/home/airflow/.local/lib/python3.7/site-packages/airflow/utils/session.py", line 70, in wrapper
    return func(*args, session=session, **kwargs)
  File "/home/airflow/.local/lib/python3.7/site-packages/airflow/models/taskinstance.py", line 1329, in _run_raw_task
    self._execute_task_with_callbacks(context)
  File "/home/airflow/.local/lib/python3.7/site-packages/airflow/models/taskinstance.py", line 1455, in _execute_task_with_callbacks
    result = self._execute_task(context, self.task)
  File "/home/airflow/.local/lib/python3.7/site-packages/airflow/models/taskinstance.py", line 1511, in _execute_task
    result = execute_callable(context=context)
  File "/home/airflow/.local/lib/python3.7/site-packages/airflow/operators/python.py", line 174, in execute
    return_value = self.execute_callable()
  File "/home/airflow/.local/lib/python3.7/site-packages/airflow/operators/python.py", line 185, in execute_callable
    return self.python_callable(*self.op_args, **self.op_kwargs)
  File "/opt/airflow/dags/data_ingestion_gcs_dag.py", line 35, in format_to_parquet
    table = pv.read_csv(csv_file)
NameError: name 'csv_file' is not defined
[2022-03-27 04:04:12,152] {local_task_job.py:154} INFO - Task exited with return code 1
[2022-03-27 04:04:12,398] {local_task_job.py:264} INFO - 0 downstream tasks scheduled from follow-on schedule check
